Workbook
Name DeliveryDays: Overall!$B$5
Name WorkingDaysPerMonth: Overall!$B$6
Name DeliveryMonths: Overall!$B$7
Name HoursPerMonth: Overall!$B$8
Name ProjectStart: Overall!$B$9
Name SprintDays: Overall!$B$10
Name HorizonYears: Overall!$B$11
Name CostEscalation: Overall!$B$12
Name HorizonFactor: Overall!$B$13
Name Contingency: Overall!$B$14
Name FxRate: Overall!$B$15
Name ClaudeFxRate: Overall!$B$16
Name LastActual: Sprints!$C$3

Sheet Overall
A1: Falcon Portal cost estimate (synthetic sample)
A2: All costs in USD. Cloud: Azure retail list prices in uaenorth fetched 2026-09-28, no discounts or reservations. Blue cells are inputs; black cells are formulas; green cells link to other sheets.
A3: Inputs
A4: Input | B4: Value
A5: Days of delivery (working days) | B5: 84
A6: Working days per month | B6: 21
A7: Months of delivery | B7: =DeliveryDays/WorkingDaysPerMonth
A8: Hours per month (always-on services) | B8: 730
A9: Delivery start date (optional; dates the epics and sprints) | B9: 46083
A10: Working days per sprint | B10: 10
A11: Years of run after go-live (3 to 5) | B11: 5
A12: Yearly increase in run costs | B12: 0.03
A13: Run years, with the yearly increase | B13: =IF(CostEscalation=0,HorizonYears,((1+CostEscalation)^HorizonYears-1)/CostEscalation)
A14: Contingency | B14: 0.1
A15: Exchange rate (1 USD = x USD) | B15: 1
A16: Exchange rate for Claude prices (1 USD = x USD) | B16: 1
A18: Delivery team (build)
A19: Role | B19: Day rate (USD) | C19: Employees | D19: Days on delivery | E19: Allocation | F19: Mandays | G19: Cost (USD) | H19: Cited from
A20: Project Manager | B20: =VLOOKUP(A20,'Rate Card'!$A$5:$B$50,2,FALSE) | C20: 1 | D20: =DeliveryDays | E20: 0.5 | F20: =C20*D20*E20 | G20: =F20*B20 | H20: owner: Delivery Manager, 2026-09-28
A21: Solution Architect | B21: =VLOOKUP(A21,'Rate Card'!$A$5:$B$50,2,FALSE) | C21: 1 | D21: 20 | E21: 1 | F21: =C21*D21*E21 | G21: =F21*B21 | H21: owner: Delivery Manager, 2026-09-28
A22: Tech Lead | B22: =VLOOKUP(A22,'Rate Card'!$A$5:$B$50,2,FALSE) | C22: 1 | D22: =DeliveryDays | E22: 1 | F22: =C22*D22*E22 | G22: =F22*B22 | H22: _bmad-output/planning-artifacts/architecture/falcon/ARCHITECTURE-SPINE.md AD-1
A23: Developer | B23: =VLOOKUP(A23,'Rate Card'!$A$5:$B$50,2,FALSE) | C23: 3 | D23: =DeliveryDays | E23: 1 | F23: =C23*D23*E23 | G23: =F23*B23 | H23: _bmad-output/specs/SPEC.md 3 Users
A24: QA Engineer | B24: =VLOOKUP(A24,'Rate Card'!$A$5:$B$50,2,FALSE) | C24: 1 | D24: =DeliveryDays | E24: 1 | F24: =C24*D24*E24 | G24: =F24*B24 | H24: owner: Delivery Manager, 2026-09-28
A25: DevOps Engineer | B25: =VLOOKUP(A25,'Rate Card'!$A$5:$B$50,2,FALSE) | C25: 1 | D25: =DeliveryDays | E25: 0.5 | F25: =C25*D25*E25 | G25: =F25*B25 | H25: _bmad-output/planning-artifacts/architecture/falcon/ARCHITECTURE-SPINE.md AD-1
B26: =IF(A26="","",VLOOKUP(A26,'Rate Card'!$A$5:$B$50,2,FALSE)) | F26: =IF(A26="","",C26*D26*E26) | G26: =IF(A26="","",F26*B26)
B27: =IF(A27="","",VLOOKUP(A27,'Rate Card'!$A$5:$B$50,2,FALSE)) | F27: =IF(A27="","",C27*D27*E27) | G27: =IF(A27="","",F27*B27)
B28: =IF(A28="","",VLOOKUP(A28,'Rate Card'!$A$5:$B$50,2,FALSE)) | F28: =IF(A28="","",C28*D28*E28) | G28: =IF(A28="","",F28*B28)
A29: Total | C29: =SUM(C20:C28) | F29: =SUM(F20:F28) | G29: =SUM(G20:G28)
A31: Run support (OPEX): IT support and maintenance after go-live
A32: Role | B32: Day rate (USD) | C32: Mandays per year | D32: Cost per year (USD) | E32: Cited from
A33: Developer | B33: =VLOOKUP(A33,'Rate Card'!$A$5:$B$50,2,FALSE) | C33: 60 | D33: =C33*B33 | E33: owner: Delivery Manager, 2026-09-28
A34: DevOps Engineer | B34: =VLOOKUP(A34,'Rate Card'!$A$5:$B$50,2,FALSE) | C34: 24 | D34: =C34*B34 | E34: owner: Delivery Manager, 2026-09-28
A35: QA Engineer | B35: =VLOOKUP(A35,'Rate Card'!$A$5:$B$50,2,FALSE) | C35: 12 | D35: =C35*B35 | E35: owner: Delivery Manager, 2026-09-28
B36: =IF(A36="","",VLOOKUP(A36,'Rate Card'!$A$5:$B$50,2,FALSE)) | D36: =IF(A36="","",C36*B36)
B37: =IF(A37="","",VLOOKUP(A37,'Rate Card'!$A$5:$B$50,2,FALSE)) | D37: =IF(A37="","",C37*B37)
B38: =IF(A38="","",VLOOKUP(A38,'Rate Card'!$A$5:$B$50,2,FALSE)) | D38: =IF(A38="","",C38*B38)
A39: Total | C39: =SUM(C33:C38) | D39: =SUM(D33:D38)
A41: Cost summary
A42: Item | B42: Monthly (USD) | C42: Months in delivery | D42: Delivery cost (USD) | E42: Run months per year | F42: Run cost per year (USD) | G42: Run cost over the horizon (USD) | H42: Total (USD) | I42: From
A43: Dev environment | B43: ='Dev'!$I$13 | C43: =DeliveryMonths | D43: =B43*C43 | E43: 12 | F43: =B43*E43 | G43: =F43*HorizonFactor | H43: =D43+G43 | I43: Dev sheet
...

Sheet Multi-Year
A1: Multi-year view
A2: In USD. Build is the delivery; each year after go-live carries the run costs, raised by the yearly increase, and the revenue given for it. Years past the horizon (Overall input) show zero. Contingency applies to every cost.
A4: Category | B4: Item | C4: Build | D4: Year 1 | E4: Year 2 | F4: Year 3 | G4: Year 4 | H4: Year 5 | I4: Total
A5: Revenue | B5: =IF('Revenue'!$B$5="","(spare revenue row)",'Revenue'!$B$5) | C5: 0 | D5: =IF(1<=HorizonYears,'Revenue'!D$5,0) | E5: =IF(2<=HorizonYears,'Revenue'!E$5,0) | F5: =IF(3<=HorizonYears,'Revenue'!F$5,0) | G5: =IF(4<=HorizonYears,'Revenue'!G$5,0) | H5: =IF(5<=HorizonYears,'Revenue'!H$5,0) | I5: =SUM(C5:H5)
A6: Revenue | B6: =IF('Revenue'!$B$6="","(spare revenue row)",'Revenue'!$B$6) | C6: 0 | D6: =IF(1<=HorizonYears,'Revenue'!D$6,0) | E6: =IF(2<=HorizonYears,'Revenue'!E$6,0) | F6: =IF(3<=HorizonYears,'Revenue'!F$6,0) | G6: =IF(4<=HorizonYears,'Revenue'!G$6,0) | H6: =IF(5<=HorizonYears,'Revenue'!H$6,0) | I6: =SUM(C6:H6)
A7: Revenue | B7: =IF('Revenue'!$B$7="","(spare revenue row)",'Revenue'!$B$7) | C7: 0 | D7: =IF(1<=HorizonYears,'Revenue'!D$7,0) | E7: =IF(2<=HorizonYears,'Revenue'!E$7,0) | F7: =IF(3<=HorizonYears,'Revenue'!F$7,0) | G7: =IF(4<=HorizonYears,'Revenue'!G$7,0) | H7: =IF(5<=HorizonYears,'Revenue'!H$7,0) | I7: =SUM(C7:H7)
A8: Revenue | B8: =IF('Revenue'!$B$8="","(spare revenue row)",'Revenue'!$B$8) | C8: 0 | D8: =IF(1<=HorizonYears,'Revenue'!D$8,0) | E8: =IF(2<=HorizonYears,'Revenue'!E$8,0) | F8: =IF(3<=HorizonYears,'Revenue'!F$8,0) | G8: =IF(4<=HorizonYears,'Revenue'!G$8,0) | H8: =IF(5<=HorizonYears,'Revenue'!H$8,0) | I8: =SUM(C8:H8)
A9: Cost | B9: Build: delivery team, environments during delivery, one-off costs | C9: ='Overall'!$D$50 | D9: 0 | E9: 0 | F9: 0 | G9: 0 | H9: 0 | I9: =SUM(C9:H9)
A10: Cost | B10: Dev environment (run) | C10: 0 | D10: =IF(1<=HorizonYears,'Overall'!$F$43*(1+CostEscalation)^0,0) | E10: =IF(2<=HorizonYears,'Overall'!$F$43*(1+CostEscalation)^1,0) | F10: =IF(3<=HorizonYears,'Overall'!$F$43*(1+CostEscalation)^2,0) | G10: =IF(4<=HorizonYears,'Overall'!$F$43*(1+CostEscalation)^3,0) | H10: =IF(5<=HorizonYears,'Overall'!$F$43*(1+CostEscalation)^4,0) | I10: =SUM(C10:H10)
A11: Cost | B11: Test environment (run) | C11: 0 | D11: =IF(1<=HorizonYears,'Overall'!$F$44*(1+CostEscalation)^0,0) | E11: =IF(2<=HorizonYears,'Overall'!$F$44*(1+CostEscalation)^1,0) | F11: =IF(3<=HorizonYears,'Overall'!$F$44*(1+CostEscalation)^2,0) | G11: =IF(4<=HorizonYears,'Overall'!$F$44*(1+CostEscalation)^3,0) | H11: =IF(5<=HorizonYears,'Overall'!$F$44*(1+CostEscalation)^4,0) | I11: =SUM(C11:H11)
A12: Cost | B12: Prod environment (run) | C12: 0 | D12: =IF(1<=HorizonYears,'Overall'!$F$45*(1+CostEscalation)^0,0) | E12: =IF(2<=HorizonYears,'Overall'!$F$45*(1+CostEscalation)^1,0) | F12: =IF(3<=HorizonYears,'Overall'!$F$45*(1+CostEscalation)^2,0) | G12: =IF(4<=HorizonYears,'Overall'!$F$45*(1+CostEscalation)^3,0) | H12: =IF(5<=HorizonYears,'Overall'!$F$45*(1+CostEscalation)^4,0) | I12: =SUM(C12:H12)
A13: Cost | B13: Run support (OPEX) | C13: 0 | D13: =IF(1<=HorizonYears,'Overall'!$F$47*(1+CostEscalation)^0,0) | E13: =IF(2<=HorizonYears,'Overall'!$F$47*(1+CostEscalation)^1,0) | F13: =IF(3<=HorizonYears,'Overall'!$F$47*(1+CostEscalation)^2,0) | G13: =IF(4<=HorizonYears,'Overall'!$F$47*(1+CostEscalation)^3,0) | H13: =IF(5<=HorizonYears,'Overall'!$F$47*(1+CostEscalation)^4,0) | I13: =SUM(C13:H13)
A14: Cost | B14: Recurring run costs | C14: 0 | D14: =IF(1<=HorizonYears,'Overall'!$F$48*(1+CostEscalation)^0,0) | E14: =IF(2<=HorizonYears,'Overall'!$F$48*(1+CostEscalation)^1,0) | F14: =IF(3<=HorizonYears,'Overall'!$F$48*(1+CostEscalation)^2,0) | G14: =IF(4<=HorizonYears,'Overall'!$F$48*(1+CostEscalation)^3,0) | H14: =IF(5<=HorizonYears,'Overall'!$F$48*(1+CostEscalation)^4,0) | I14: =SUM(C14:H14)
A15: Contingency | B15: Contingency on every cost | C15: =SUMIF($A$5:$A$14,"Cost",C5:C14)*Contingency | D15: =SUMIF($A$5:$A$14,"Cost",D5:D14)*Contingency | E15: =SUMIF($A$5:$A$14,"Cost",E5:E14)*Contingency | F15: =SUMIF($A$5:$A$14,"Cost",F5:F14)*Contingency | G15: =SUMIF($A$5:$A$14,"Cost",G5:G14)*Contingency | H15: =SUMIF($A$5:$A$14,"Cost",H5:H14)*Contingency | I15: =SUM(C15:H15)
A16: Total revenue | C16: =SUMIF($A$5:$A$15,"Revenue",C5:C15) | D16: =SUMIF($A$5:$A$15,"Revenue",D5:D15) | E16: =SUMIF($A$5:$A$15,"Revenue",E5:E15) | F16: =SUMIF($A$5:$A$15,"Revenue",F5:F15) | G16: =SUMIF($A$5:$A$15,"Revenue",G5:G15) | H16: =SUMIF($A$5:$A$15,"Revenue",H5:H15) | I16: =SUMIF($A$5:$A$15,"Revenue",I5:I15)
A17: Total costs | C17: =SUMIF($A$5:$A$15,"Cost",C5:C15)+SUMIF($A$5:$A$15,"Contingency",C5:C15) | D17: =SUMIF($A$5:$A$15,"Cost",D5:D15)+SUMIF($A$5:$A$15,"Contingency",D5:D15) | E17: =SUMIF($A$5:$A$15,"Cost",E5:E15)+SUMIF($A$5:$A$15,"Contingency",E5:E15) | F17: =SUMIF($A$5:$A$15,"Cost",F5:F15)+SUMIF($A$5:$A$15,"Contingency",F5:F15) | G17: =SUMIF($A$5:$A$15,"Cost",G5:G15)+SUMIF($A$5:$A$15,"Contingency",G5:G15) | H17: =SUMIF($A$5:$A$15,"Cost",H5:H15)+SUMIF($A$5:$A$15,"Contingency",H5:H15) | I17: =SUMIF($A$5:$A$15,"Cost",I5:I15)+SUMIF($A$5:$A$15,"Contingency",I5:I15)
A18: Net | C18: =C16-C17 | D18: =D16-D17 | E18: =E16-E17 | F18: =F16-F17 | G18: =G16-G17 | H18: =H16-H17 | I18: =I16-I17
A19: Cumulative net | C19: =C18 | D19: =C19+D18 | E19: =D19+E18 | F19: =E19+F18 | G19: =F19+G18 | H19: =G19+H18 | I19: =H19
A21: Payback | B21: =IF(C19>=0,"Build",IF(D19>=0,"Year 1",IF(E19>=0,"Year 2",IF(F19>=0,"Year 3",IF(G19>=0,"Year 4",IF(H19>=0,"Year 5","beyond the horizon"))))))
A22: Return on cost (net / costs) | B22: =IF(I17=0,"",I18/I17)

Sheet Epics
A1: Epics: deliverables, forecast and actual
A2: In USD. Forecast: each epic takes a share of the build in proportion to its planned working days (that share of the delivery team and of the environments during delivery), plus the one-off costs tagged to it and its Claude API budget; dates run the epics one after another from the delivery start date. Actual: enter or keep the actual start and end dates; actual working days, the Claude API actual from the ledger, and team and infra scaled by actual / planned days (same team and rates) unless you enter the timesheet team cost. Blue cells are inputs; add an epic in a spare row.
A4: Epic | B4: Name | C4: Deliverables | D4: Planned days | E4: Planned weeks | F4: Planned start | G4: Planned end | H4: Share of build | I4: Team mandays | J4: Team cost (USD) | K4: Infra cost (USD) | L4: Other costs (USD) | M4: Claude API budget (USD) | N4: Forecast total (USD) | O4: Actual start | P4: Actual end | Q4: Actual days | R4: Days variance | S4: Days variance % | T4: Claude API actual (USD) | U4: Actual team cost, timesheets (USD) | V4: Actual total (USD) | W4: Cost variance (USD) | X4: Cited from
A5: 1 | B5: Customer onboarding | C5: 1.1 Sign in with Entra ID 1.2 Start an application 1.3 Upload documents | D5: 40 | E5: =IF(D5="","",D5/5) | F5: =IF(OR(D5="",ProjectStart=""),"",ProjectStart) | G5: =IF(F5="","",WORKDAY(F5,D5-1)) | H5: =IF(D5="","",D5/SUM($D$5:$D$9)) | I5: =IF(D5="","",H5*'Overall'!$F$29) | J5: =IF(D5="","",H5*'Overall'!$G$29) | K5: =IF(D5="","",H5*('Overall'!$D$43+'Overall'!$D$44+'Overall'!$D$45)) | L5: =IF(A5="","",SUMIFS('Other Costs'!$C$5:$C$9,'Other Costs'!$F$5:$F$9,A5)) | M5: 150 | N5: =IF(D5="","",J5+K5+L5+N(M5)) | O5: 46083 | P5: 46132 | Q5: =IF(OR(D5="",O5="",P5=""),"",NETWORKDAYS(O5,P5)) | R5: =IF(Q5="","",Q5-D5) | S5: =IF(Q5="","",Q5/D5-1) | T5: =IF(A5="","",SUMIFS('Claude Usage Detail'!$P$5:$P$19,'Claude Usage Detail'!$C$5:$C$19,A5&".*")) | V5: =IF(Q5="","",IF(U5="",J5*Q5/D5,U5)+K5*Q5/D5+L5+N(T5)) | W5: =IF(V5="","",V5-N5) | X5: _bmad-output/planning-artifacts/epics.md Epic 1: Customer onboarding
A6: 2 | B6: Review and decision | C6: 2.1 Review queue 2.2 Approve or reject 2.3 Notify the customer | D6: 44 | E6: =IF(D6="","",D6/5) | F6: =IF(OR(D6="",ProjectStart=""),"",WORKDAY(G5,1)) | G6: =IF(F6="","",WORKDAY(F6,D6-1)) | H6: =IF(D6="","",D6/SUM($D$5:$D$9)) | I6: =IF(D6="","",H6*'Overall'!$F$29) | J6: =IF(D6="","",H6*'Overall'!$G$29) | K6: =IF(D6="","",H6*('Overall'!$D$43+'Overall'!$D$44+'Overall'!$D$45)) | L6: =IF(A6="","",SUMIFS('Other Costs'!$C$5:$C$9,'Other Costs'!$F$5:$F$9,A6)) | M6: 150 | N6: =IF(D6="","",J6+K6+L6+N(M6)) | O6: 46133 | P6: 46199 | Q6: =IF(OR(D6="",O6="",P6=""),"",NETWORKDAYS(O6,P6)) | R6: =IF(Q6="","",Q6-D6) | S6: =IF(Q6="","",Q6/D6-1) | T6: =IF(A6="","",SUMIFS('Claude Usage Detail'!$P$5:$P$19,'Claude Usage Detail'!$C$5:$C$19,A6&".*")) | V6: =IF(Q6="","",IF(U6="",J6*Q6/D6,U6)+K6*Q6/D6+L6+N(T6)) | W6: =IF(V6="","",V6-N6) | X6: _bmad-output/planning-artifacts/epics.md Epic 2: Review and decision
E7: =IF(D7="","",D7/5) | F7: =IF(OR(D7="",ProjectStart=""),"",WORKDAY(G6,1)) | G7: =IF(F7="","",WORKDAY(F7,D7-1)) | H7: =IF(D7="","",D7/SUM($D$5:$D$9)) | I7: =IF(D7="","",H7*'Overall'!$F$29) | J7: =IF(D7="","",H7*'Overall'!$G$29) | K7: =IF(D7="","",H7*('Overall'!$D$43+'Overall'!$D$44+'Overall'!$D$45)) | L7: =IF(A7="","",SUMIFS('Other Costs'!$C$5:$C$9,'Other Costs'!$F$5:$F$9,A7)) | N7: =IF(D7="","",J7+K7+L7+N(M7)) | Q7: =IF(OR(D7="",O7="",P7=""),"",NETWORKDAYS(O7,P7)) | R7: =IF(Q7="","",Q7-D7) | S7: =IF(Q7="","",Q7/D7-1) | T7: =IF(A7="","",SUMIFS('Claude Usage Detail'!$P$5:$P$19,'Claude Usage Detail'!$C$5:$C$19,A7&".*")) | V7: =IF(Q7="","",IF(U7="",J7*Q7/D7,U7)+K7*Q7/D7+L7+N(T7)) | W7: =IF(V7="","",V7-N7)
E8: =IF(D8="","",D8/5) | F8: =IF(OR(D8="",ProjectStart=""),"",WORKDAY(G7,1)) | G8: =IF(F8="","",WORKDAY(F8,D8-1)) | H8: =IF(D8="","",D8/SUM($D$5:$D$9)) | I8: =IF(D8="","",H8*'Overall'!$F$29) | J8: =IF(D8="","",H8*'Overall'!$G$29) | K8: =IF(D8="","",H8*('Overall'!$D$43+'Overall'!$D$44+'Overall'!$D$45)) | L8: =IF(A8="","",SUMIFS('Other Costs'!$C$5:$C$9,'Other Costs'!$F$5:$F$9,A8)) | N8: =IF(D8="","",J8+K8+L8+N(M8)) | Q8: =IF(OR(D8="",O8="",P8=""),"",NETWORKDAYS(O8,P8)) | R8: =IF(Q8="","",Q8-D8) | S8: =IF(Q8="","",Q8/D8-1) | T8: =IF(A8="","",SUMIFS('Claude Usage Detail'!$P$5:$P$19,'Claude Usage Detail'!$C$5:$C$19,A8&".*")) | V8: =IF(Q8="","",IF(U8="",J8*Q8/D8,U8)+K8*Q8/D8+L8+N(T8)) | W8: =IF(V8="","",V8-N8)
E9: =IF(D9="","",D9/5) | F9: =IF(OR(D9="",ProjectStart=""),"",WORKDAY(G8,1)) | G9: =IF(F9="","",WORKDAY(F9,D9-1)) | H9: =IF(D9="","",D9/SUM($D$5:$D$9)) | I9: =IF(D9="","",H9*'Overall'!$F$29) | J9: =IF(D9="","",H9*'Overall'!$G$29) | K9: =IF(D9="","",H9*('Overall'!$D$43+'Overall'!$D$44+'Overall'!$D$45)) | L9: =IF(A9="","",SUMIFS('Other Costs'!$C$5:$C$9,'Other Costs'!$F$5:$F$9,A9)) | N9: =IF(D9="","",J9+K9+L9+N(M9)) | Q9: =IF(OR(D9="",O9="",P9=""),"",NETWORKDAYS(O9,P9)) | R9: =IF(Q9="","",Q9-D9) | S9: =IF(Q9="","",Q9/D9-1) | T9: =IF(A9="","",SUMIFS('Claude Usage Detail'!$P$5:$P$19,'Claude Usage Detail'!$C$5:$C$19,A9&".*")) | V9: =IF(Q9="","",IF(U9="",J9*Q9/D9,U9)+K9*Q9/D9+L9+N(T9)) | W9: =IF(V9="","",V9-N9)
A10: Total | D10: =SUM(D5:D9) | I10: =SUM(I5:I9) | J10: =SUM(J5:J9) | K10: =SUM(K5:K9) | L10: =SUM(L5:L9) | M10: =SUM(M5:M9) | N10: =SUM(N5:N9) | Q10: =SUM(Q5:Q9) | R10: =SUM(R5:R9) | S10: =IF(Q10=0,"",Q10/SUMIFS(D5:D9,Q5:Q9,">0")-1) | T10: =SUM(T5:T9) | U10: =SUM(U5:U9) | V10: =SUM(V5:V9) | W10: =SUM(W5:W9)
A12: =IF(D10=DeliveryDays,"The planned epics add up to the days of delivery.","The planned epics add up to "&D10&" working days; the days of delivery input is "&DeliveryDays&". Costs are shared by planned epic days either way.")

Sheet Sprints
A1: Sprints: forecast and actual
A2: In USD. Every sprint is a timebox of the Overall input 'Working days per sprint' from the delivery start date. Forecast: the sprint's planned working days (the days of delivery, sprint by sprint) at the delivery team's and the environments' daily cost, plus any Claude API budget. Actual, up to the last actual activity (the latest completed story or day of Claude usage): the days worked in the sprint, the stories completed, the Claude API cost on its days, and the team at the days worked unless timesheets are entered. Sprints past the plan appear when work ran over. Blue cells are inputs.
A3: Last actual activity | C3: =IF(MAX(MAXIFS('Project Timeline'!$F$5:$F$20,'Project Timeline'!$A$5:$A$20,"story"),MAX('Claude Usage Daily'!$A$5:$A$233))=0,"",MAX(MAXIFS('Project Timeline'!$F$5:$F$20,'Project Timeline'!$A$5:$A$20,"story"),MAX('Claude Usage Daily'!$A$5:$A$233)))
A4: Sprint | B4: Start | C4: End | D4: Planned days | E4: Planned stories | F4: Team cost (USD) | G4: Infra cost (USD) | H4: Claude API budget (USD) | I4: Forecast total (USD) | J4: Days worked | K4: Stories done | L4: Stories done (list) | M4: Claude API actual (USD) | N4: Actual team cost, timesheets (USD) | O4: Actual total (USD) | P4: Cost variance (USD)
A5: 1 | B5: =IF(OR(D5="",ProjectStart=""),"",WORKDAY(ProjectStart,(1-1)*SprintDays)) | C5: =IF(B5="","",WORKDAY(B5,SprintDays-1)) | D5: =IF(OR(MIN(SprintDays,MAX(0,DeliveryDays-(1-1)*SprintDays))>0,AND(ProjectStart<>"",LastActual<>"",WORKDAY(ProjectStart,(1-1)*SprintDays)<=N(LastActual))),MIN(SprintDays,MAX(0,DeliveryDays-(1-1)*SprintDays)),"") | E5: 1.1 Sign in with Entra ID | F5: =IF(D5="","",D5*'Overall'!$G$29/DeliveryDays) | G5: =IF(D5="","",D5*('Overall'!$D$43+'Overall'!$D$44+'Overall'!$D$45)/DeliveryDays) | I5: =IF(D5="","",F5+G5+N(H5)) | J5: =IF(OR(B5="",LastActual="",B5>N(LastActual)),"",NETWORKDAYS(B5,MIN(C5,LastActual))) | K5: =IF(J5="","",COUNTIFS('Project Timeline'!$A$5:$A$20,"story",'Project Timeline'!$F$5:$F$20,">="&B5,'Project Timeline'!$F$5:$F$20,"<="&C5)) | M5: =IF(J5="","",SUMIFS('Claude Usage Daily'!$O$5:$O$233,'Claude Usage Daily'!$A$5:$A$233,">="&B5,'Claude Usage Daily'!$A$5:$A$233,"<="&C5)) | O5: =IF(J5="","",IF(N5="",J5*'Overall'!$G$29/DeliveryDays,N5)+J5*('Overall'!$D$43+'Overall'!$D$44+'Overall'!$D$45)/DeliveryDays+N(M5)) | P5: =IF(O5="","",O5-N(I5))
A6: 2 | B6: =IF(OR(D6="",ProjectStart=""),"",WORKDAY(ProjectStart,(2-1)*SprintDays)) | C6: =IF(B6="","",WORKDAY(B6,SprintDays-1)) | D6: =IF(OR(MIN(SprintDays,MAX(0,DeliveryDays-(2-1)*SprintDays))>0,AND(ProjectStart<>"",LastActual<>"",WORKDAY(ProjectStart,(2-1)*SprintDays)<=N(LastActual))),MIN(SprintDays,MAX(0,DeliveryDays-(2-1)*SprintDays)),"") | E6: 1.2 Start an application | F6: =IF(D6="","",D6*'Overall'!$G$29/DeliveryDays) | G6: =IF(D6="","",D6*('Overall'!$D$43+'Overall'!$D$44+'Overall'!$D$45)/DeliveryDays) | I6: =IF(D6="","",F6+G6+N(H6)) | J6: =IF(OR(B6="",LastActual="",B6>N(LastActual)),"",NETWORKDAYS(B6,MIN(C6,LastActual))) | K6: =IF(J6="","",COUNTIFS('Project Timeline'!$A$5:$A$20,"story",'Project Timeline'!$F$5:$F$20,">="&B6,'Project Timeline'!$F$5:$F$20,"<="&C6)) | L6: 1-1-sign-in | M6: =IF(J6="","",SUMIFS('Claude Usage Daily'!$O$5:$O$233,'Claude Usage Daily'!$A$5:$A$233,">="&B6,'Claude Usage Daily'!$A$5:$A$233,"<="&C6)) | O6: =IF(J6="","",IF(N6="",J6*'Overall'!$G$29/DeliveryDays,N6)+J6*('Overall'!$D$43+'Overall'!$D$44+'Overall'!$D$45)/DeliveryDays+N(M6)) | P6: =IF(O6="","",O6-N(I6))
A7: 3 | B7: =IF(OR(D7="",ProjectStart=""),"",WORKDAY(ProjectStart,(3-1)*SprintDays)) | C7: =IF(B7="","",WORKDAY(B7,SprintDays-1)) | D7: =IF(OR(MIN(SprintDays,MAX(0,DeliveryDays-(3-1)*SprintDays))>0,AND(ProjectStart<>"",LastActual<>"",WORKDAY(ProjectStart,(3-1)*SprintDays)<=N(LastActual))),MIN(SprintDays,MAX(0,DeliveryDays-(3-1)*SprintDays)),"") | E7: 1.2 Start an application 1.3 Upload documents | F7: =IF(D7="","",D7*'Overall'!$G$29/DeliveryDays) | G7: =IF(D7="","",D7*('Overall'!$D$43+'Overall'!$D$44+'Overall'!$D$45)/DeliveryDays) | I7: =IF(D7="","",F7+G7+N(H7)) | J7: =IF(OR(B7="",LastActual="",B7>N(LastActual)),"",NETWORKDAYS(B7,MIN(C7,LastActual))) | K7: =IF(J7="","",COUNTIFS('Project Timeline'!$A$5:$A$20,"story",'Project Timeline'!$F$5:$F$20,">="&B7,'Project Timeline'!$F$5:$F$20,"<="&C7)) | L7: 1-2-start-application | M7: =IF(J7="","",SUMIFS('Claude Usage Daily'!$O$5:$O$233,'Claude Usage Daily'!$A$5:$A$233,">="&B7,'Claude Usage Daily'!$A$5:$A$233,"<="&C7)) | O7: =IF(J7="","",IF(N7="",J7*'Overall'!$G$29/DeliveryDays,N7)+J7*('Overall'!$D$43+'Overall'!$D$44+'Overall'!$D$45)/DeliveryDays+N(M7)) | P7: =IF(O7="","",O7-N(I7))
A8: 4 | B8: =IF(OR(D8="",ProjectStart=""),"",WORKDAY(ProjectStart,(4-1)*SprintDays)) | C8: =IF(B8="","",WORKDAY(B8,SprintDays-1)) | D8: =IF(OR(MIN(SprintDays,MAX(0,DeliveryDays-(4-1)*SprintDays))>0,AND(ProjectStart<>"",LastActual<>"",WORKDAY(ProjectStart,(4-1)*SprintDays)<=N(LastActual))),MIN(SprintDays,MAX(0,DeliveryDays-(4-1)*SprintDays)),"") | E8: 1.3 Upload documents | F8: =IF(D8="","",D8*'Overall'!$G$29/DeliveryDays) | G8: =IF(D8="","",D8*('Overall'!$D$43+'Overall'!$D$44+'Overall'!$D$45)/DeliveryDays) | I8: =IF(D8="","",F8+G8+N(H8)) | J8: =IF(OR(B8="",LastActual="",B8>N(LastActual)),"",NETWORKDAYS(B8,MIN(C8,LastActual))) | K8: =IF(J8="","",COUNTIFS('Project Timeline'!$A$5:$A$20,"story",'Project Timeline'!$F$5:$F$20,">="&B8,'Project Timeline'!$F$5:$F$20,"<="&C8)) | L8: 1-3-upload-documents | M8: =IF(J8="","",SUMIFS('Claude Usage Daily'!$O$5:$O$233,'Claude Usage Daily'!$A$5:$A$233,">="&B8,'Claude Usage Daily'!$A$5:$A$233,"<="&C8)) | O8: =IF(J8="","",IF(N8="",J8*'Overall'!$G$29/DeliveryDays,N8)+J8*('Overall'!$D$43+'Overall'!$D$44+'Overall'!$D$45)/DeliveryDays+N(M8)) | P8: =IF(O8="","",O8-N(I8))
A9: 5 | B9: =IF(OR(D9="",ProjectStart=""),"",WORKDAY(ProjectStart,(5-1)*SprintDays)) | C9: =IF(B9="","",WORKDAY(B9,SprintDays-1)) | D9: =IF(OR(MIN(SprintDays,MAX(0,DeliveryDays-(5-1)*SprintDays))>0,AND(ProjectStart<>"",LastActual<>"",WORKDAY(ProjectStart,(5-1)*SprintDays)<=N(LastActual))),MIN(SprintDays,MAX(0,DeliveryDays-(5-1)*SprintDays)),"") | E9: 2.1 Review queue | F9: =IF(D9="","",D9*'Overall'!$G$29/DeliveryDays) | G9: =IF(D9="","",D9*('Overall'!$D$43+'Overall'!$D$44+'Overall'!$D$45)/DeliveryDays) | I9: =IF(D9="","",F9+G9+N(H9)) | J9: =IF(OR(B9="",LastActual="",B9>N(LastActual)),"",NETWORKDAYS(B9,MIN(C9,LastActual))) | K9: =IF(J9="","",COUNTIFS('Project Timeline'!$A$5:$A$20,"story",'Project Timeline'!$F$5:$F$20,">="&B9,'Project Timeline'!$F$5:$F$20,"<="&C9)) | M9: =IF(J9="","",SUMIFS('Claude Usage Daily'!$O$5:$O$233,'Claude Usage Daily'!$A$5:$A$233,">="&B9,'Claude Usage Daily'!$A$5:$A$233,"<="&C9)) | O9: =IF(J9="","",IF(N9="",J9*'Overall'!$G$29/DeliveryDays,N9)+J9*('Overall'!$D$43+'Overall'!$D$44+'Overall'!$D$45)/DeliveryDays+N(M9)) | P9: =IF(O9="","",O9-N(I9))
A10: 6 | B10: =IF(OR(D10="",ProjectStart=""),"",WORKDAY(ProjectStart,(6-1)*SprintDays)) | C10: =IF(B10="","",WORKDAY(B10,SprintDays-1)) | D10: =IF(OR(MIN(SprintDays,MAX(0,DeliveryDays-(6-1)*SprintDays))>0,AND(ProjectStart<>"",LastActual<>"",WORKDAY(ProjectStart,(6-1)*SprintDays)<=N(LastActual))),MIN(SprintDays,MAX(0,DeliveryDays-(6-1)*SprintDays)),"") | E10: 2.1 Review queue 2.2 Approve or reject | F10: =IF(D10="","",D10*'Overall'!$G$29/DeliveryDays) | G10: =IF(D10="","",D10*('Overall'!$D$43+'Overall'!$D$44+'Overall'!$D$45)/DeliveryDays) | I10: =IF(D10="","",F10+G10+N(H10)) | J10: =IF(OR(B10="",LastActual="",B10>N(LastActual)),"",NETWORKDAYS(B10,MIN(C10,LastActual))) | K10: =IF(J10="","",COUNTIFS('Project Timeline'!$A$5:$A$20,"story",'Project Timeline'!$F$5:$F$20,">="&B10,'Project Timeline'!$F$5:$F$20,"<="&C10)) | L10: 2-1-review-queue | M10: =IF(J10="","",SUMIFS('Claude Usage Daily'!$O$5:$O$233,'Claude Usage Daily'!$A$5:$A$233,">="&B10,'Claude Usage Daily'!$A$5:$A$233,"<="&C10)) | O10: =IF(J10="","",IF(N10="",J10*'Overall'!$G$29/DeliveryDays,N10)+J10*('Overall'!$D$43+'Overall'!$D$44+'Overall'!$D$45)/DeliveryDays+N(M10)) | P10: =IF(O10="","",O10-N(I10))
A11: 7 | B11: =IF(OR(D11="",ProjectStart=""),"",WORKDAY(ProjectStart,(7-1)*SprintDays)) | C11: =IF(B11="","",WORKDAY(B11,SprintDays-1)) | D11: =IF(OR(MIN(SprintDays,MAX(0,DeliveryDays-(7-1)*SprintDays))>0,AND(ProjectStart<>"",LastActual<>"",WORKDAY(ProjectStart,(7-1)*SprintDays)<=N(LastActual))),MIN(SprintDays,MAX(0,DeliveryDays-(7-1)*SprintDays)),"") | E11: 2.2 Approve or reject | F11: =IF(D11="","",D11*'Overall'!$G$29/DeliveryDays) | G11: =IF(D11="","",D11*('Overall'!$D$43+'Overall'!$D$44+'Overall'!$D$45)/DeliveryDays) | I11: =IF(D11="","",F11+G11+N(H11)) | J11: =IF(OR(B11="",LastActual="",B11>N(LastActual)),"",NETWORKDAYS(B11,MIN(C11,LastActual))) | K11: =IF(J11="","",COUNTIFS('Project Timeline'!$A$5:$A$20,"story",'Project Timeline'!$F$5:$F$20,">="&B11,'Project Timeline'!$F$5:$F$20,"<="&C11)) | L11: 2-2-approve-or-reject | M11: =IF(J11="","",SUMIFS('Claude Usage Daily'!$O$5:$O$233,'Claude Usage Daily'!$A$5:$A$233,">="&B11,'Claude Usage Daily'!$A$5:$A$233,"<="&C11)) | O11: =IF(J11="","",IF(N11="",J11*'Overall'!$G$29/DeliveryDays,N11)+J11*('Overall'!$D$43+'Overall'!$D$44+'Overall'!$D$45)/DeliveryDays+N(M11)) | P11: =IF(O11="","",O11-N(I11))
A12: 8 | B12: =IF(OR(D12="",ProjectStart=""),"",WORKDAY(ProjectStart,(8-1)*SprintDays)) | C12: =IF(B12="","",WORKDAY(B12,SprintDays-1)) | D12: =IF(OR(MIN(SprintDays,MAX(0,DeliveryDays-(8-1)*SprintDays))>0,AND(ProjectStart<>"",LastActual<>"",WORKDAY(ProjectStart,(8-1)*SprintDays)<=N(LastActual))),MIN(SprintDays,MAX(0,DeliveryDays-(8-1)*SprintDays)),"") | E12: 2.3 Notify the customer | F12: =IF(D12="","",D12*'Overall'!$G$29/DeliveryDays) | G12: =IF(D12="","",D12*('Overall'!$D$43+'Overall'!$D$44+'Overall'!$D$45)/DeliveryDays) | I12: =IF(D12="","",F12+G12+N(H12)) | J12: =IF(OR(B12="",LastActual="",B12>N(LastActual)),"",NETWORKDAYS(B12,MIN(C12,LastActual))) | K12: =IF(J12="","",COUNTIFS('Project Timeline'!$A$5:$A$20,"story",'Project Timeline'!$F$5:$F$20,">="&B12,'Project Timeline'!$F$5:$F$20,"<="&C12)) | M12: =IF(J12="","",SUMIFS('Claude Usage Daily'!$O$5:$O$233,'Claude Usage Daily'!$A$5:$A$233,">="&B12,'Claude Usage Daily'!$A$5:$A$233,"<="&C12)) | O12: =IF(J12="","",IF(N12="",J12*'Overall'!$G$29/DeliveryDays,N12)+J12*('Overall'!$D$43+'Overall'!$D$44+'Overall'!$D$45)/DeliveryDays+N(M12)) | P12: =IF(O12="","",O12-N(I12))
A13: 9 | B13: =IF(OR(D13="",ProjectStart=""),"",WORKDAY(ProjectStart,(9-1)*SprintDays)) | C13: =IF(B13="","",WORKDAY(B13,SprintDays-1)) | D13: =IF(OR(MIN(SprintDays,MAX(0,DeliveryDays-(9-1)*SprintDays))>0,AND(ProjectStart<>"",LastActual<>"",WORKDAY(ProjectStart,(9-1)*SprintDays)<=N(LastActual))),MIN(SprintDays,MAX(0,DeliveryDays-(9-1)*SprintDays)),"") | E13: 2.3 Notify the customer | F13: =IF(D13="","",D13*'Overall'!$G$29/DeliveryDays) | G13: =IF(D13="","",D13*('Overall'!$D$43+'Overall'!$D$44+'Overall'!$D$45)/DeliveryDays) | I13: =IF(D13="","",F13+G13+N(H13)) | J13: =IF(OR(B13="",LastActual="",B13>N(LastActual)),"",NETWORKDAYS(B13,MIN(C13,LastActual))) | K13: =IF(J13="","",COUNTIFS('Project Timeline'!$A$5:$A$20,"story",'Project Timeline'!$F$5:$F$20,">="&B13,'Project Timeline'!$F$5:$F$20,"<="&C13)) | L13: 2-3-notify-customer | M13: =IF(J13="","",SUMIFS('Claude Usage Daily'!$O$5:$O$233,'Claude Usage Daily'!$A$5:$A$233,">="&B13,'Claude Usage Daily'!$A$5:$A$233,"<="&C13)) | O13: =IF(J13="","",IF(N13="",J13*'Overall'!$G$29/DeliveryDays,N13)+J13*('Overall'!$D$43+'Overall'!$D$44+'Overall'!$D$45)/DeliveryDays+N(M13)) | P13: =IF(O13="","",O13-N(I13))
A14: 10 | B14: =IF(OR(D14="",ProjectStart=""),"",WORKDAY(ProjectStart,(10-1)*SprintDays)) | C14: =IF(B14="","",WORKDAY(B14,SprintDays-1)) | D14: =IF(OR(MIN(SprintDays,MAX(0,DeliveryDays-(10-1)*SprintDays))>0,AND(ProjectStart<>"",LastActual<>"",WORKDAY(ProjectStart,(10-1)*SprintDays)<=N(LastActual))),MIN(SprintDays,MAX(0,DeliveryDays-(10-1)*SprintDays)),"") | F14: =IF(D14="","",D14*'Overall'!$G$29/DeliveryDays) | G14: =IF(D14="","",D14*('Overall'!$D$43+'Overall'!$D$44+'Overall'!$D$45)/DeliveryDays) | I14: =IF(D14="","",F14+G14+N(H14)) | J14: =IF(OR(B14="",LastActual="",B14>N(LastActual)),"",NETWORKDAYS(B14,MIN(C14,LastActual))) | K14: =IF(J14="","",COUNTIFS('Project Timeline'!$A$5:$A$20,"story",'Project Timeline'!$F$5:$F$20,">="&B14,'Project Timeline'!$F$5:$F$20,"<="&C14)) | M14: =IF(J14="","",SUMIFS('Claude Usage Daily'!$O$5:$O$233,'Claude Usage Daily'!$A$5:$A$233,">="&B14,'Claude Usage Daily'!$A$5:$A$233,"<="&C14)) | O14: =IF(J14="","",IF(N14="",J14*'Overall'!$G$29/DeliveryDays,N14)+J14*('Overall'!$D$43+'Overall'!$D$44+'Overall'!$D$45)/DeliveryDays+N(M14)) | P14: =IF(O14="","",O14-N(I14))
A15: 11 | B15: =IF(OR(D15="",ProjectStart=""),"",WORKDAY(ProjectStart,(11-1)*SprintDays)) | C15: =IF(B15="","",WORKDAY(B15,SprintDays-1)) | D15: =IF(OR(MIN(SprintDays,MAX(0,DeliveryDays-(11-1)*SprintDays))>0,AND(ProjectStart<>"",LastActual<>"",WORKDAY(ProjectStart,(11-1)*SprintDays)<=N(LastActual))),MIN(SprintDays,MAX(0,DeliveryDays-(11-1)*SprintDays)),"") | F15: =IF(D15="","",D15*'Overall'!$G$29/DeliveryDays) | G15: =IF(D15="","",D15*('Overall'!$D$43+'Overall'!$D$44+'Overall'!$D$45)/DeliveryDays) | I15: =IF(D15="","",F15+G15+N(H15)) | J15: =IF(OR(B15="",LastActual="",B15>N(LastActual)),"",NETWORKDAYS(B15,MIN(C15,LastActual))) | K15: =IF(J15="","",COUNTIFS('Project Timeline'!$A$5:$A$20,"story",'Project Timeline'!$F$5:$F$20,">="&B15,'Project Timeline'!$F$5:$F$20,"<="&C15)) | M15: =IF(J15="","",SUMIFS('Claude Usage Daily'!$O$5:$O$233,'Claude Usage Daily'!$A$5:$A$233,">="&B15,'Claude Usage Daily'!$A$5:$A$233,"<="&C15)) | O15: =IF(J15="","",IF(N15="",J15*'Overall'!$G$29/DeliveryDays,N15)+J15*('Overall'!$D$43+'Overall'!$D$44+'Overall'!$D$45)/DeliveryDays+N(M15)) | P15: =IF(O15="","",O15-N(I15))
A16: 12 | B16: =IF(OR(D16="",ProjectStart=""),"",WORKDAY(ProjectStart,(12-1)*SprintDays)) | C16: =IF(B16="","",WORKDAY(B16,SprintDays-1)) | D16: =IF(OR(MIN(SprintDays,MAX(0,DeliveryDays-(12-1)*SprintDays))>0,AND(ProjectStart<>"",LastActual<>"",WORKDAY(ProjectStart,(12-1)*SprintDays)<=N(LastActual))),MIN(SprintDays,MAX(0,DeliveryDays-(12-1)*SprintDays)),"") | F16: =IF(D16="","",D16*'Overall'!$G$29/DeliveryDays) | G16: =IF(D16="","",D16*('Overall'!$D$43+'Overall'!$D$44+'Overall'!$D$45)/DeliveryDays) | I16: =IF(D16="","",F16+G16+N(H16)) | J16: =IF(OR(B16="",LastActual="",B16>N(LastActual)),"",NETWORKDAYS(B16,MIN(C16,LastActual))) | K16: =IF(J16="","",COUNTIFS('Project Timeline'!$A$5:$A$20,"story",'Project Timeline'!$F$5:$F$20,">="&B16,'Project Timeline'!$F$5:$F$20,"<="&C16)) | M16: =IF(J16="","",SUMIFS('Claude Usage Daily'!$O$5:$O$233,'Claude Usage Daily'!$A$5:$A$233,">="&B16,'Claude Usage Daily'!$A$5:$A$233,"<="&C16)) | O16: =IF(J16="","",IF(N16="",J16*'Overall'!$G$29/DeliveryDays,N16)+J16*('Overall'!$D$43+'Overall'!$D$44+'Overall'!$D$45)/DeliveryDays+N(M16)) | P16: =IF(O16="","",O16-N(I16))
A17: Total | D17: =SUM(D5:D16) | F17: =SUM(F5:F16) | G17: =SUM(G5:G16) | H17: =SUM(H5:H16) | I17: =SUM(I5:I16) | J17: =SUM(J5:J16) | K17: =SUM(K5:K16) | M17: =SUM(M5:M16) | N17: =SUM(N5:N16) | O17: =SUM(O5:O16) | P17: =SUM(P5:P16)

Sheet Phase Budgets
A1: Phase budgets: Claude API budget and actual per planning phase
A2: In USD, at Claude API list prices. The budget each planning phase may spend (test design, governance, diagrams, course corrections ...), set once the epics and sprint plan are done; the epics and sprints carry their own budgets on their sheets. Actual: the phase's Claude cost from the ledger (Claude Usage Detail) once the close-out sheets are in. A control figure: not added to any total. Blue cells are inputs; name a phase as the token ledger does.
A4: Phase | B4: Claude API budget (USD) | C4: Claude API actual (USD) | D4: Variance (USD) | E4: Variance % | F4: Cited from
A5: governance (Jules) | B5: 40 | C5: =IF(A5="","",SUMIFS('Claude Usage Detail'!$P$5:$P$19,'Claude Usage Detail'!$B$5:$B$19,A5)) | D5: =IF(OR(A5="",C5=""),"",C5-N(B5)) | E5: =IF(OR(D5="",N(B5)=0),"",C5/B5-1) | F5: owner: Delivery Manager (synthetic), 2026-09-28
A6: architecture docs (Da Vinci) | B6: 25 | C6: =IF(A6="","",SUMIFS('Claude Usage Detail'!$P$5:$P$19,'Claude Usage Detail'!$B$5:$B$19,A6)) | D6: =IF(OR(A6="",C6=""),"",C6-N(B6)) | E6: =IF(OR(D6="",N(B6)=0),"",C6/B6-1) | F6: owner: Delivery Manager (synthetic), 2026-09-28
A7: test design | B7: 30 | C7: =IF(A7="","",SUMIFS('Claude Usage Detail'!$P$5:$P$19,'Claude Usage Detail'!$B$5:$B$19,A7)) | D7: =IF(OR(A7="",C7=""),"",C7-N(B7)) | E7: =IF(OR(D7="",N(B7)=0),"",C7/B7-1) | F7: owner: Delivery Manager (synthetic), 2026-09-28
C8: =IF(A8="","",SUMIFS('Claude Usage Detail'!$P$5:$P$19,'Claude Usage Detail'!$B$5:$B$19,A8)) | D8: =IF(OR(A8="",C8=""),"",C8-N(B8)) | E8: =IF(OR(D8="",N(B8)=0),"",C8/B8-1)
C9: =IF(A9="","",SUMIFS('Claude Usage Detail'!$P$5:$P$19,'Claude Usage Detail'!$B$5:$B$19,A9)) | D9: =IF(OR(A9="",C9=""),"",C9-N(B9)) | E9: =IF(OR(D9="",N(B9)=0),"",C9/B9-1)
C10: =IF(A10="","",SUMIFS('Claude Usage Detail'!$P$5:$P$19,'Claude Usage Detail'!$B$5:$B$19,A10)) | D10: =IF(OR(A10="",C10=""),"",C10-N(B10)) | E10: =IF(OR(D10="",N(B10)=0),"",C10/B10-1)
A11: Total | B11: =SUM(B5:B10) | C11: =SUM(C5:C10) | D11: =SUM(D5:D10)

Sheet Revenue
A1: Revenue
A2: Revenue the solution earns, per year after go-live, in USD, from the owner or the business case; each stream cites its source. Years past the horizon are ignored. Blue cells are inputs.
A4: # | B4: Stream | C4: Basis | D4: Year 1 | E4: Year 2 | F4: Year 3 | G4: Year 4 | H4: Year 5 | I4: Cited from | J4: Note
A5: 1 | B5: Application processing fees | C5: $10 per application; 30,000 in year 1, +25% a year | D5: 300000 | E5: 375000 | F5: 468750 | G5: 585938 | H5: 732422 | I5: _bmad-output/specs/SPEC.md 7 Business case
A9: Total | D9: =SUM(D5:D8) | E9: =SUM(E5:E8) | F9: =SUM(F5:F8) | G9: =SUM(G5:G8) | H9: =SUM(H5:H8)

Sheet Rate Card
A1: Employee rate card
A2: Day rates in USD. Source: Synthetic sample rates, not a real rate card; updated 2026-09-28. Blue cells are inputs; the team and support tables look roles up here.
A4: Role | B4: Day rate (USD) | C4: Note
A5: Project Manager | B5: 760
A6: Solution Architect | B6: 950
A7: Tech Lead | B7: 870
A8: Developer | B8: 650
A9: QA Engineer | B9: 545
A10: DevOps Engineer | B10: 710

Sheet Other Costs
A1: Other one-off costs
A2: Licences, tests, training and other one-off costs of the build, outside the environments and the team, in USD.
A4: # | B4: Item | C4: Amount (USD) | D4: Cited from | E4: Note | F4: Epic
A5: 1 | B5: Penetration test | C5: 12000 | D5: owner: Security Lead, 2026-09-28 | F5: 2
A6: 2 | B6: GitHub Enterprise seats (12 months) | C6: 8700 | D6: assumption: 7 seats at list price
A10: Total | C10: =SUM(C5:C9)

Sheet Run Costs
A1: Recurring run costs (OPEX)
A2: Yearly costs of running the solution outside the cloud environments and the support team: support contracts, licences, subscriptions. In USD per year; the Multi-Year sheet escalates them by the yearly increase.
A4: # | B4: Item | C4: Annual cost (USD) | D4: Cited from | E4: Note
A5: 1 | B5: Azure support plan (Standard) | C5: 1200 | D5: assumption: Standard support at list price
A6: 2 | B6: GitHub Enterprise seats (4 for support) | C6: 1000 | D6: assumption: 4 seats at list price
A10: Total | C10: =SUM(C5:C9)

Sheet Dev
A1: Dev environment
A2: Azure retail list prices (pay-as-you-go) in uaenorth, USD, fetched 2026-09-28. Daily cost is the monthly cost spread over the year (x 12 / 365). Blue cells are inputs.
A4: # | B4: Component | C4: Azure service | D4: SKU / tier | E4: Unit | F4: Unit price (USD) | G4: Quantity | H4: Usage per month | I4: Monthly cost (USD) | J4: Daily cost (USD) | K4: Annual cost (USD) | L4: Cited from | M4: Price source | N4: Note | O4: Environment
A5: 1 | B5: AKS nodes | C5: Virtual Machines | D5: Standard_D4s_v5 | E5: 1 Hour | F5: 0.235 | G5: 2 | H5: 220 | I5: =F5*G5*H5*FxRate | J5: =I5*12/365 | K5: =I5*12 | L5: _bmad-output/planning-artifacts/architecture/falcon/ARCHITECTURE-SPINE.md AD-1 | M5: Azure Retail Prices API, Virtual Machines Dsv5 Series / D4s v5, uaenorth, USD per 1 Hour, meterId 75a8da05-74dd-5b32-bb86-4f5cc74cdb60, fetched 2026-09-28 | N5: Dev nodes stopped outside working hours | O5: Dev
A6: 2 | B6: Customer database | C6: SQL Database | D6: General Purpose Gen5, 2 vCore | E6: 1 vCore Hour | F6: 0.253 | G6: 2 | H6: =HoursPerMonth | I6: =F6*G6*H6*FxRate | J6: =I6*12/365 | K6: =I6*12 | L6: _bmad-output/planning-artifacts/architecture/falcon/ARCHITECTURE-SPINE.md AD-2 | M6: Synthetic sample price (not looked up) | O6: Dev
A7: 3 | B7: Document storage | C7: Storage | D7: Blob Hot LRS | E7: 1 GB/Month | F7: 0.019 | G7: 50 | H7: 1 | I7: =F7*G7*H7*FxRate | J7: =I7*12/365 | K7: =I7*12 | L7: assumption: 50 GB of test documents | M7: Synthetic sample price (not looked up) | O7: Dev
A8: 4 | B8: Secrets | C8: Key Vault | D8: Standard | E8: 10K operations | F8: 0.03 | G8: 30 | H8: 1 | I8: =F8*G8*H8*FxRate | J8: =I8*12/365 | K8: =I8*12 | L8: _bmad-output/planning-artifacts/architecture/falcon/ARCHITECTURE-SPINE.md AD-5 | M8: Synthetic sample price (not looked up) | O8: Dev
A9: 5 | B9: Logs and metrics | C9: Log Analytics | D9: Pay-as-you-go | E9: 1 GB | F9: 2.76 | G9: 5 | H9: 1 | I9: =F9*G9*H9*FxRate | J9: =I9*12/365 | K9: =I9*12 | L9: _bmad-output/planning-artifacts/architecture/falcon/ARCHITECTURE-SPINE.md AD-5 | M9: Synthetic sample price (not looked up) | O9: Dev
I10: =IF(F10="","",F10*G10*H10*FxRate) | J10: =IF(I10="","",I10*12/365) | K10: =IF(I10="","",I10*12) | O10: Dev
I11: =IF(F11="","",F11*G11*H11*FxRate) | J11: =IF(I11="","",I11*12/365) | K11: =IF(I11="","",I11*12) | O11: Dev
I12: =IF(F12="","",F12*G12*H12*FxRate) | J12: =IF(I12="","",I12*12/365) | K12: =IF(I12="","",I12*12) | O12: Dev
A13: Total | I13: =SUM(I5:I12) | J13: =SUM(J5:J12) | K13: =SUM(K5:K12)

Sheet Test
A1: Test environment
A2: Azure retail list prices (pay-as-you-go) in uaenorth, USD, fetched 2026-09-28. Daily cost is the monthly cost spread over the year (x 12 / 365). Blue cells are inputs.
A4: # | B4: Component | C4: Azure service | D4: SKU / tier | E4: Unit | F4: Unit price (USD) | G4: Quantity | H4: Usage per month | I4: Monthly cost (USD) | J4: Daily cost (USD) | K4: Annual cost (USD) | L4: Cited from | M4: Price source | N4: Note | O4: Environment
A5: 1 | B5: AKS nodes | C5: Virtual Machines | D5: Standard_D4s_v5 | E5: 1 Hour | F5: 0.235 | G5: 2 | H5: =HoursPerMonth | I5: =F5*G5*H5*FxRate | J5: =I5*12/365 | K5: =I5*12 | L5: _bmad-output/planning-artifacts/architecture/falcon/ARCHITECTURE-SPINE.md AD-1 | M5: Azure Retail Prices API, Virtual Machines Dsv5 Series / D4s v5, uaenorth, USD per 1 Hour, meterId 75a8da05-74dd-5b32-bb86-4f5cc74cdb60, fetched 2026-09-28 | O5: Test
A6: 2 | B6: Customer database | C6: SQL Database | D6: General Purpose Gen5, 2 vCore | E6: 1 vCore Hour | F6: 0.253 | G6: 2 | H6: =HoursPerMonth | I6: =F6*G6*H6*FxRate | J6: =I6*12/365 | K6: =I6*12 | L6: _bmad-output/planning-artifacts/architecture/falcon/ARCHITECTURE-SPINE.md AD-2 | M6: Synthetic sample price (not looked up) | O6: Test
A7: 3 | B7: Document storage | C7: Storage | D7: Blob Hot LRS | E7: 1 GB/Month | F7: 0.019 | G7: 50 | H7: 1 | I7: =F7*G7*H7*FxRate | J7: =I7*12/365 | K7: =I7*12 | L7: assumption: 50 GB of test documents | M7: Synthetic sample price (not looked up) | O7: Test
A8: 4 | B8: Secrets | C8: Key Vault | D8: Standard | E8: 10K operations | F8: 0.03 | G8: 30 | H8: 1 | I8: =F8*G8*H8*FxRate | J8: =I8*12/365 | K8: =I8*12 | L8: _bmad-output/planning-artifacts/architecture/falcon/ARCHITECTURE-SPINE.md AD-5 | M8: Synthetic sample price (not looked up) | O8: Test
A9: 5 | B9: Logs and metrics | C9: Log Analytics | D9: Pay-as-you-go | E9: 1 GB | F9: 2.76 | G9: 5 | H9: 1 | I9: =F9*G9*H9*FxRate | J9: =I9*12/365 | K9: =I9*12 | L9: _bmad-output/planning-artifacts/architecture/falcon/ARCHITECTURE-SPINE.md AD-5 | M9: Synthetic sample price (not looked up) | O9: Test
A10: 6 | B10: Edge | C10: Azure Front Door Service | D10: Standard base fee | E10: 1 Month | F10: 35 | G10: 1 | H10: 1 | I10: =F10*G10*H10*FxRate | J10: =I10*12/365 | K10: =I10*12 | L10: _bmad-output/planning-artifacts/architecture/falcon/ARCHITECTURE-SPINE.md AD-4 | M10: Synthetic sample price (not looked up) | O10: Test
I11: =IF(F11="","",F11*G11*H11*FxRate) | J11: =IF(I11="","",I11*12/365) | K11: =IF(I11="","",I11*12) | O11: Test
I12: =IF(F12="","",F12*G12*H12*FxRate) | J12: =IF(I12="","",I12*12/365) | K12: =IF(I12="","",I12*12) | O12: Test
I13: =IF(F13="","",F13*G13*H13*FxRate) | J13: =IF(I13="","",I13*12/365) | K13: =IF(I13="","",I13*12) | O13: Test
A14: Total | I14: =SUM(I5:I13) | J14: =SUM(J5:J13) | K14: =SUM(K5:K13)

Sheet Prod
A1: Prod environment
A2: Azure retail list prices (pay-as-you-go) in uaenorth, USD, fetched 2026-09-28. Daily cost is the monthly cost spread over the year (x 12 / 365). Blue cells are inputs.
A4: # | B4: Component | C4: Azure service | D4: SKU / tier | E4: Unit | F4: Unit price (USD) | G4: Quantity | H4: Usage per month | I4: Monthly cost (USD) | J4: Daily cost (USD) | K4: Annual cost (USD) | L4: Cited from | M4: Price source | N4: Note | O4: Environment
A5: 1 | B5: AKS nodes | C5: Virtual Machines | D5: Standard_D4s_v5 | E5: 1 Hour | F5: 0.235 | G5: 3 | H5: =HoursPerMonth | I5: =F5*G5*H5*FxRate | J5: =I5*12/365 | K5: =I5*12 | L5: _bmad-output/planning-artifacts/architecture/falcon/ARCHITECTURE-SPINE.md AD-1 | M5: Azure Retail Prices API, Virtual Machines Dsv5 Series / D4s v5, uaenorth, USD per 1 Hour, meterId 75a8da05-74dd-5b32-bb86-4f5cc74cdb60, fetched 2026-09-28 | O5: Prod
A6: 2 | B6: Customer database | C6: SQL Database | D6: General Purpose Gen5, 4 vCore | E6: 1 vCore Hour | F6: 0.253 | G6: 4 | H6: =HoursPerMonth | I6: =F6*G6*H6*FxRate | J6: =I6*12/365 | K6: =I6*12 | L6: _bmad-output/planning-artifacts/architecture/falcon/ARCHITECTURE-SPINE.md AD-2 | M6: Synthetic sample price (not looked up) | O6: Prod
A7: 3 | B7: Document storage | C7: Storage | D7: Blob Hot LRS | E7: 1 GB/Month | F7: 0.019 | G7: 500 | H7: 1 | I7: =F7*G7*H7*FxRate | J7: =I7*12/365 | K7: =I7*12 | L7: _bmad-output/planning-artifacts/architecture/falcon/ARCHITECTURE-SPINE.md AD-3 | M7: Synthetic sample price (not looked up) | O7: Prod
A8: 4 | B8: Secrets | C8: Key Vault | D8: Standard | E8: 10K operations | F8: 0.03 | G8: 30 | H8: 1 | I8: =F8*G8*H8*FxRate | J8: =I8*12/365 | K8: =I8*12 | L8: _bmad-output/planning-artifacts/architecture/falcon/ARCHITECTURE-SPINE.md AD-5 | M8: Synthetic sample price (not looked up) | O8: Prod
A9: 5 | B9: Logs and metrics | C9: Log Analytics | D9: Pay-as-you-go | E9: 1 GB | F9: 2.76 | G9: 30 | H9: 1 | I9: =F9*G9*H9*FxRate | J9: =I9*12/365 | K9: =I9*12 | L9: _bmad-output/planning-artifacts/architecture/falcon/ARCHITECTURE-SPINE.md AD-5 | M9: Synthetic sample price (not looked up) | O9: Prod
A10: 6 | B10: Edge | C10: Azure Front Door Service | D10: Standard base fee | E10: 1 Month | F10: 35 | G10: 1 | H10: 1 | I10: =F10*G10*H10*FxRate | J10: =I10*12/365 | K10: =I10*12 | L10: _bmad-output/planning-artifacts/architecture/falcon/ARCHITECTURE-SPINE.md AD-4 | M10: Synthetic sample price (not looked up) | O10: Prod
I11: =IF(F11="","",F11*G11*H11*FxRate) | J11: =IF(I11="","",I11*12/365) | K11: =IF(I11="","",I11*12) | O11: Prod
I12: =IF(F12="","",F12*G12*H12*FxRate) | J12: =IF(I12="","",I12*12/365) | K12: =IF(I12="","",I12*12) | O12: Prod
I13: =IF(F13="","",F13*G13*H13*FxRate) | J13: =IF(I13="","",I13*12/365) | K13: =IF(I13="","",I13*12) | O13: Prod
A14: Total | I14: =SUM(I5:I13) | J14: =SUM(J5:J13) | K14: =SUM(K5:K13)

Sheet Claude Prices
A1: Claude API list prices
A2: USD per million tokens, from https://platform.claude.com/docs/en/about-claude/pricing, read 2026-09-28. Blue cells are inputs.
A4: Pricing model | B4: Name | C4: Input | D4: Cache write 5m | E4: Cache write 1h | F4: Cache read | G4: Output
A5: claude-fable-5 | B5: Claude Fable 5 | C5: 10 | D5: 12.5 | E5: 20 | F5: 1 | G5: 50
A6: claude-fable-5-1 | B6: Claude Fable 5.1 | C6: 10 | D6: 12.5 | E6: 20 | F6: 0.25 | G6: 50
A7: claude-haiku-3-5 | B7: Claude Haiku 3.5 | C7: 0.8 | D7: 1 | E7: 1.6 | F7: 0.08 | G7: 4
A8: claude-haiku-4-5 | B8: Claude Haiku 4.5 | C8: 1 | D8: 1.25 | E8: 2 | F8: 0.1 | G8: 5
A9: claude-mythos-5 | B9: Claude Mythos 5 | C9: 10 | D9: 12.5 | E9: 20 | F9: 1 | G9: 50
A10: claude-mythos-5-1 | B10: Claude Mythos 5.1 | C10: 10 | D10: 12.5 | E10: 20 | F10: 0.25 | G10: 50
A11: claude-opus-4 | B11: Claude Opus 4 | C11: 15 | D11: 18.75 | E11: 30 | F11: 1.5 | G11: 75
A12: claude-opus-4-1 | B12: Claude Opus 4.1 | C12: 15 | D12: 18.75 | E12: 30 | F12: 1.5 | G12: 75
A13: claude-opus-4-5 | B13: Claude Opus 4.5 | C13: 5 | D13: 6.25 | E13: 10 | F13: 0.5 | G13: 25
A14: claude-opus-4-6 | B14: Claude Opus 4.6 | C14: 5 | D14: 6.25 | E14: 10 | F14: 0.5 | G14: 25
A15: claude-opus-4-7 | B15: Claude Opus 4.7 | C15: 5 | D15: 6.25 | E15: 10 | F15: 0.5 | G15: 25
A16: claude-opus-4-8 | B16: Claude Opus 4.8 | C16: 5 | D16: 6.25 | E16: 10 | F16: 0.5 | G16: 25
... A22: claude-sonnet-5 | B22: Claude Sonnet 5 | C22: 2 | D22: 2.5 | E22: 4 | F22: 0.2 | G22: 10

Sheet Claude Usage
A1: Claude API usage
A2: API calls and tokens counted from this project's Claude Code logs, costed at Claude API list prices. On a Pro, Max, Team or Enterprise subscription the bill is per seat: this is the API-equivalent cost.
A4: Model | B4: Calls | C4: Input tokens | D4: Cache write 5m tokens | E4: Cache write 1h tokens | F4: Cache read tokens | G4: Output tokens | H4: Cost (USD) | I4: Cost (USD)
A5: claude-haiku-4-5-20251001 | B5: =SUMIFS('Claude Usage Detail'!$I$5:$I$19,'Claude Usage Detail'!$E$5:$E$19,"="&$A5) | C5: =SUMIFS('Claude Usage Detail'!$J$5:$J$19,'Claude Usage Detail'!$E$5:$E$19,"="&$A5) | D5: =SUMIFS('Claude Usage Detail'!$K$5:$K$19,'Claude Usage Detail'!$E$5:$E$19,"="&$A5) | E5: =SUMIFS('Claude Usage Detail'!$L$5:$L$19,'Claude Usage Detail'!$E$5:$E$19,"="&$A5) | F5: =SUMIFS('Claude Usage Detail'!$M$5:$M$19,'Claude Usage Detail'!$E$5:$E$19,"="&$A5) | G5: =SUMIFS('Claude Usage Detail'!$N$5:$N$19,'Claude Usage Detail'!$E$5:$E$19,"="&$A5) | H5: =SUMIFS('Claude Usage Detail'!$O$5:$O$19,'Claude Usage Detail'!$E$5:$E$19,"="&$A5) | I5: =SUMIFS('Claude Usage Detail'!$P$5:$P$19,'Claude Usage Detail'!$E$5:$E$19,"="&$A5)
A6: claude-opus-5-5 | B6: =SUMIFS('Claude Usage Detail'!$I$5:$I$19,'Claude Usage Detail'!$E$5:$E$19,"="&$A6) | C6: =SUMIFS('Claude Usage Detail'!$J$5:$J$19,'Claude Usage Detail'!$E$5:$E$19,"="&$A6) | D6: =SUMIFS('Claude Usage Detail'!$K$5:$K$19,'Claude Usage Detail'!$E$5:$E$19,"="&$A6) | E6: =SUMIFS('Claude Usage Detail'!$L$5:$L$19,'Claude Usage Detail'!$E$5:$E$19,"="&$A6) | F6: =SUMIFS('Claude Usage Detail'!$M$5:$M$19,'Claude Usage Detail'!$E$5:$E$19,"="&$A6) | G6: =SUMIFS('Claude Usage Detail'!$N$5:$N$19,'Claude Usage Detail'!$E$5:$E$19,"="&$A6) | H6: =SUMIFS('Claude Usage Detail'!$O$5:$O$19,'Claude Usage Detail'!$E$5:$E$19,"="&$A6) | I6: =SUMIFS('Claude Usage Detail'!$P$5:$P$19,'Claude Usage Detail'!$E$5:$E$19,"="&$A6)
A7: claude-sonnet-5 | B7: =SUMIFS('Claude Usage Detail'!$I$5:$I$19,'Claude Usage Detail'!$E$5:$E$19,"="&$A7) | C7: =SUMIFS('Claude Usage Detail'!$J$5:$J$19,'Claude Usage Detail'!$E$5:$E$19,"="&$A7) | D7: =SUMIFS('Claude Usage Detail'!$K$5:$K$19,'Claude Usage Detail'!$E$5:$E$19,"="&$A7) | E7: =SUMIFS('Claude Usage Detail'!$L$5:$L$19,'Claude Usage Detail'!$E$5:$E$19,"="&$A7) | F7: =SUMIFS('Claude Usage Detail'!$M$5:$M$19,'Claude Usage Detail'!$E$5:$E$19,"="&$A7) | G7: =SUMIFS('Claude Usage Detail'!$N$5:$N$19,'Claude Usage Detail'!$E$5:$E$19,"="&$A7) | H7: =SUMIFS('Claude Usage Detail'!$O$5:$O$19,'Claude Usage Detail'!$E$5:$E$19,"="&$A7) | I7: =SUMIFS('Claude Usage Detail'!$P$5:$P$19,'Claude Usage Detail'!$E$5:$E$19,"="&$A7)
A8: Total | B8: =SUM(B5:B7) | C8: =SUM(C5:C7) | D8: =SUM(D5:D7) | E8: =SUM(E5:E7) | F8: =SUM(F5:F7) | G8: =SUM(G5:G7) | H8: =SUM(H5:H7) | I8: =SUM(I5:I7)

Sheet Claude Usage Detail
A1: Claude API calls by work item and model
A2: From the token ledger (claude_usage.csv). Cost = tokens x the Claude Prices sheet; models with no price cost 0.
A4: Kind | B4: Work item | C4: Story no | D4: Title | E4: Model | F4: Pricing model | G4: First call | H4: Last call | I4: Calls | J4: Input tokens | K4: Cache write 5m tokens | L4: Cache write 1h tokens | M4: Cache read tokens | N4: Output tokens | O4: Cost (USD) | P4: Cost (USD)
A5: planning | B5: brainstorming | E5: claude-opus-5-5 | F5: claude-opus-5-5 | G5: 46027.375 | H5: 46027.708 | I5: 42 | J5: 9000 | K5: 120000 | L5: 380000 | M5: 6100000 | N5: 95000 | O5: =IFERROR((J5*VLOOKUP($F5,'Claude Prices'!$A$5:$G$22,3,FALSE)+K5*VLOOKUP($F5,'Claude Prices'!$A$5:$G$22,4,FALSE)+L5*VLOOKUP($F5,'Claude Prices'!$A$5:$G$22,5,FALSE)+M5*VLOOKUP($F5,'Claude Prices'!$A$5:$G$22,6,FALSE)+N5*VLOOKUP($F5,'Claude Prices'!$A$5:$G$22,7,FALSE))/1000000,0) | P5: =O5*ClaudeFxRate
A6: planning | B6: spec | E6: claude-opus-5-5 | F6: claude-opus-5-5 | G6: 46028.375 | H6: 46030.708 | I6: 118 | J6: 21000 | K6: 300000 | L6: 1250000 | M6: 21400000 | N6: 310000 | O6: =IFERROR((J6*VLOOKUP($F6,'Claude Prices'!$A$5:$G$22,3,FALSE)+K6*VLOOKUP($F6,'Claude Prices'!$A$5:$G$22,4,FALSE)+L6*VLOOKUP($F6,'Claude Prices'!$A$5:$G$22,5,FALSE)+M6*VLOOKUP($F6,'Claude Prices'!$A$5:$G$22,6,FALSE)+N6*VLOOKUP($F6,'Claude Prices'!$A$5:$G$22,7,FALSE))/1000000,0) | P6: =O6*ClaudeFxRate
A7: planning | B7: architecture | E7: claude-opus-5-5 | F7: claude-opus-5-5 | G7: 46034.375 | H7: 46044.708 | I7: 356 | J7: 64000 | K7: 820000 | L7: 3900000 | M7: 68200000 | N7: 905000 | O7: =IFERROR((J7*VLOOKUP($F7,'Claude Prices'!$A$5:$G$22,3,FALSE)+K7*VLOOKUP($F7,'Claude Prices'!$A$5:$G$22,4,FALSE)+L7*VLOOKUP($F7,'Claude Prices'!$A$5:$G$22,5,FALSE)+M7*VLOOKUP($F7,'Claude Prices'!$A$5:$G$22,6,FALSE)+N7*VLOOKUP($F7,'Claude Prices'!$A$5:$G$22,7,FALSE))/1000000,0) | P7: =O7*ClaudeFxRate
A8: planning | B8: UX design | E8: claude-sonnet-5 | F8: claude-sonnet-5 | G8: 46041.375 | H8: 46045.708 | I8: 164 | J8: 30000 | K8: 410000 | L8: 1500000 | M8: 24800000 | N8: 420000 | O8: =IFERROR((J8*VLOOKUP($F8,'Claude Prices'!$A$5:$G$22,3,FALSE)+K8*VLOOKUP($F8,'Claude Prices'!$A$5:$G$22,4,FALSE)+L8*VLOOKUP($F8,'Claude Prices'!$A$5:$G$22,5,FALSE)+M8*VLOOKUP($F8,'Claude Prices'!$A$5:$G$22,6,FALSE)+N8*VLOOKUP($F8,'Claude Prices'!$A$5:$G$22,7,FALSE))/1000000,0) | P8: =O8*ClaudeFxRate
A9: planning | B9: epics & stories | E9: claude-sonnet-5 | F9: claude-sonnet-5 | G9: 46048.375 | H9: 46049.708 | I9: 97 | J9: 18000 | K9: 260000 | L9: 900000 | M9: 14600000 | N9: 260000 | O9: =IFERROR((J9*VLOOKUP($F9,'Claude Prices'!$A$5:$G$22,3,FALSE)+K9*VLOOKUP($F9,'Claude Prices'!$A$5:$G$22,4,FALSE)+L9*VLOOKUP($F9,'Claude Prices'!$A$5:$G$22,5,FALSE)+M9*VLOOKUP($F9,'Claude Prices'!$A$5:$G$22,6,FALSE)+N9*VLOOKUP($F9,'Claude Prices'!$A$5:$G$22,7,FALSE))/1000000,0) | P9: =O9*ClaudeFxRate
A10: planning | B10: governance (Jules) | E10: claude-opus-5-5 | F10: claude-opus-5-5 | G10: 46042.375 | H10: 46073.708 | I10: 88 | J10: 15000 | K10: 210000 | L10: 760000 | M10: 12500000 | N10: 180000 | O10: =IFERROR((J10*VLOOKUP($F10,'Claude Prices'!$A$5:$G$22,3,FALSE)+K10*VLOOKUP($F10,'Claude Prices'!$A$5:$G$22,4,FALSE)+L10*VLOOKUP($F10,'Claude Prices'!$A$5:$G$22,5,FALSE)+M10*VLOOKUP($F10,'Claude Prices'!$A$5:$G$22,6,FALSE)+N10*VLOOKUP($F10,'Claude Prices'!$A$5:$G$22,7,FALSE))/1000000,0) | P10: =O10*ClaudeFxRate
A11: planning | B11: architecture docs (Da Vinci) | E11: claude-opus-5-5 | F11: claude-opus-5-5 | G11: 46042.375 | H11: 46044.708 | I11: 61 | J11: 11000 | K11: 150000 | L11: 520000 | M11: 8700000 | N11: 140000 | O11: =IFERROR((J11*VLOOKUP($F11,'Claude Prices'!$A$5:$G$22,3,FALSE)+K11*VLOOKUP($F11,'Claude Prices'!$A$5:$G$22,4,FALSE)+L11*VLOOKUP($F11,'Claude Prices'!$A$5:$G$22,5,FALSE)+M11*VLOOKUP($F11,'Claude Prices'!$A$5:$G$22,6,FALSE)+N11*VLOOKUP($F11,'Claude Prices'!$A$5:$G$22,7,FALSE))/1000000,0) | P11: =O11*ClaudeFxRate
A12: story | B12: FAL-11 | C12: 1.1 | D12: Sign in with Entra ID | E12: claude-sonnet-5 | F12: claude-sonnet-5 | G12: 46083.375 | H12: 46098.708 | I12: 212 | J12: 40000 | K12: 500000 | L12: 2100000 | M12: 33900000 | N12: 520000 | O12: =IFERROR((J12*VLOOKUP($F12,'Claude Prices'!$A$5:$G$22,3,FALSE)+K12*VLOOKUP($F12,'Claude Prices'!$A$5:$G$22,4,FALSE)+L12*VLOOKUP($F12,'Claude Prices'!$A$5:$G$22,5,FALSE)+M12*VLOOKUP($F12,'Claude Prices'!$A$5:$G$22,6,FALSE)+N12*VLOOKUP($F12,'Claude Prices'!$A$5:$G$22,7,FALSE))/1000000,0) | P12: =O12*ClaudeFxRate
A13: story | B13: FAL-12 | C13: 1.2 | D13: Start an application | E13: claude-sonnet-5 | F13: claude-sonnet-5 | G13: 46099.375 | H13: 46114.708 | I13: 305 | J13: 57000 | K13: 720000 | L13: 3000000 | M13: 48700000 | N13: 760000 | O13: =IFERROR((J13*VLOOKUP($F13,'Claude Prices'!$A$5:$G$22,3,FALSE)+K13*VLOOKUP($F13,'Claude Prices'!$A$5:$G$22,4,FALSE)+L13*VLOOKUP($F13,'Claude Prices'!$A$5:$G$22,5,FALSE)+M13*VLOOKUP($F13,'Claude Prices'!$A$5:$G$22,6,FALSE)+N13*VLOOKUP($F13,'Claude Prices'!$A$5:$G$22,7,FALSE))/1000000,0) | P13: =O13*ClaudeFxRate
A14: story | B14: FAL-13 | C14: 1.3 | D14: Upload documents | E14: claude-sonnet-5 | F14: claude-sonnet-5 | G14: 46115.375 | H14: 46132.708 | I14: 248 | J14: 46000 | K14: 600000 | L14: 2500000 | M14: 40100000 | N14: 610000 | O14: =IFERROR((J14*VLOOKUP($F14,'Claude Prices'!$A$5:$G$22,3,FALSE)+K14*VLOOKUP($F14,'Claude Prices'!$A$5:$G$22,4,FALSE)+L14*VLOOKUP($F14,'Claude Prices'!$A$5:$G$22,5,FALSE)+M14*VLOOKUP($F14,'Claude Prices'!$A$5:$G$22,6,FALSE)+N14*VLOOKUP($F14,'Claude Prices'!$A$5:$G$22,7,FALSE))/1000000,0) | P14: =O14*ClaudeFxRate
A15: story | B15: FAL-13 | C15: 1.3 | D15: Upload documents | E15: claude-haiku-4-5-20251001 | F15: claude-haiku-4-5 | G15: 46115.375 | H15: 46132.708 | I15: 96 | J15: 18000 | K15: 90000 | L15: 300000 | M15: 6200000 | N15: 70000 | O15: =IFERROR((J15*VLOOKUP($F15,'Claude Prices'!$A$5:$G$22,3,FALSE)+K15*VLOOKUP($F15,'Claude Prices'!$A$5:$G$22,4,FALSE)+L15*VLOOKUP($F15,'Claude Prices'!$A$5:$G$22,5,FALSE)+M15*VLOOKUP($F15,'Claude Prices'!$A$5:$G$22,6,FALSE)+N15*VLOOKUP($F15,'Claude Prices'!$A$5:$G$22,7,FALSE))/1000000,0) | P15: =O15*ClaudeFxRate
A16: story | B16: FAL-21 | C16: 2.1 | D16: Review queue | E16: claude-sonnet-5 | F16: claude-sonnet-5 | G16: 46133.375 | H16: 46154.708 | I16: 289 | J16: 54000 | K16: 690000 | L16: 2900000 | M16: 46300000 | N16: 710000 | O16: =IFERROR((J16*VLOOKUP($F16,'Claude Prices'!$A$5:$G$22,3,FALSE)+K16*VLOOKUP($F16,'Claude Prices'!$A$5:$G$22,4,FALSE)+L16*VLOOKUP($F16,'Claude Prices'!$A$5:$G$22,5,FALSE)+M16*VLOOKUP($F16,'Claude Prices'!$A$5:$G$22,6,FALSE)+N16*VLOOKUP($F16,'Claude Prices'!$A$5:$G$22,7,FALSE))/1000000,0) | P16: =O16*ClaudeFxRate
A17: story | B17: FAL-22 | C17: 2.2 | D17: Approve or reject | E17: claude-sonnet-5 | F17: claude-sonnet-5 | G17: 46155.375 | H17: 46176.708 | I17: 231 | J17: 43000 | K17: 560000 | L17: 2300000 | M17: 37000000 | N17: 570000 | O17: =IFERROR((J17*VLOOKUP($F17,'Claude Prices'!$A$5:$G$22,3,FALSE)+K17*VLOOKUP($F17,'Claude Prices'!$A$5:$G$22,4,FALSE)+L17*VLOOKUP($F17,'Claude Prices'!$A$5:$G$22,5,FALSE)+M17*VLOOKUP($F17,'Claude Prices'!$A$5:$G$22,6,FALSE)+N17*VLOOKUP($F17,'Claude Prices'!$A$5:$G$22,7,FALSE))/1000000,0) | P17: =O17*ClaudeFxRate
A18: story | B18: FAL-23 | C18: 2.3 | D18: Notify the customer | E18: claude-sonnet-5 | F18: claude-sonnet-5 | G18: 46177.375 | H18: 46199.708 | I18: 174 | J18: 32000 | K18: 420000 | L18: 1700000 | M18: 27800000 | N18: 430000 | O18: =IFERROR((J18*VLOOKUP($F18,'Claude Prices'!$A$5:$G$22,3,FALSE)+K18*VLOOKUP($F18,'Claude Prices'!$A$5:$G$22,4,FALSE)+L18*VLOOKUP($F18,'Claude Prices'!$A$5:$G$22,5,FALSE)+M18*VLOOKUP($F18,'Claude Prices'!$A$5:$G$22,6,FALSE)+N18*VLOOKUP($F18,'Claude Prices'!$A$5:$G$22,7,FALSE))/1000000,0) | P18: =O18*ClaudeFxRate
A19: ops | B19: merges, promotions & deploys | E19: claude-haiku-4-5-20251001 | F19: claude-haiku-4-5 | G19: 46083.375 | H19: 46199.708 | I19: 133 | J19: 25000 | K19: 110000 | L19: 420000 | M19: 8600000 | N19: 95000 | O19: =IFERROR((J19*VLOOKUP($F19,'Claude Prices'!$A$5:$G$22,3,FALSE)+K19*VLOOKUP($F19,'Claude Prices'!$A$5:$G$22,4,FALSE)+L19*VLOOKUP($F19,'Claude Prices'!$A$5:$G$22,5,FALSE)+M19*VLOOKUP($F19,'Claude Prices'!$A$5:$G$22,6,FALSE)+N19*VLOOKUP($F19,'Claude Prices'!$A$5:$G$22,7,FALSE))/1000000,0) | P19: =O19*ClaudeFxRate

Sheet Claude Usage Daily
A1: Claude API usage by day
A2: From the token ledger (claude_usage_daily.csv, refreshed after every turn). Cost = tokens x the Claude Prices sheet; models with no price cost 0.
A4: Day | B4: Kind | C4: Work item | D4: Story no | E4: Title | F4: Model | G4: Pricing model | H4: Calls | I4: Input tokens | J4: Cache write 5m tokens | K4: Cache write 1h tokens | L4: Cache read tokens | M4: Output tokens | N4: Cost (USD) | O4: Cost (USD)
A5: 46027 | B5: planning | C5: brainstorming | F5: claude-opus-5-5 | G5: claude-opus-5-5 | H5: 42 | I5: 9000 | J5: 120000 | K5: 380000 | L5: 6100000 | M5: 95000 | N5: =IFERROR((I5*VLOOKUP($G5,'Claude Prices'!$A$5:$G$22,3,FALSE)+J5*VLOOKUP($G5,'Claude Prices'!$A$5:$G$22,4,FALSE)+K5*VLOOKUP($G5,'Claude Prices'!$A$5:$G$22,5,FALSE)+L5*VLOOKUP($G5,'Claude Prices'!$A$5:$G$22,6,FALSE)+M5*VLOOKUP($G5,'Claude Prices'!$A$5:$G$22,7,FALSE))/1000000,0) | O5: =N5*ClaudeFxRate
A6: 46028 | B6: planning | C6: spec | F6: claude-opus-5-5 | G6: claude-opus-5-5 | H6: 39 | I6: 7000 | J6: 100000 | K6: 416666 | L6: 7133333 | M6: 103333 | N6: =IFERROR((I6*VLOOKUP($G6,'Claude Prices'!$A$5:$G$22,3,FALSE)+J6*VLOOKUP($G6,'Claude Prices'!$A$5:$G$22,4,FALSE)+K6*VLOOKUP($G6,'Claude Prices'!$A$5:$G$22,5,FALSE)+L6*VLOOKUP($G6,'Claude Prices'!$A$5:$G$22,6,FALSE)+M6*VLOOKUP($G6,'Claude Prices'!$A$5:$G$22,7,FALSE))/1000000,0) | O6: =N6*ClaudeFxRate
A7: 46029 | B7: planning | C7: spec | F7: claude-opus-5-5 | G7: claude-opus-5-5 | H7: 39 | I7: 7000 | J7: 100000 | K7: 416666 | L7: 7133333 | M7: 103333 | N7: =IFERROR((I7*VLOOKUP($G7,'Claude Prices'!$A$5:$G$22,3,FALSE)+J7*VLOOKUP($G7,'Claude Prices'!$A$5:$G$22,4,FALSE)+K7*VLOOKUP($G7,'Claude Prices'!$A$5:$G$22,5,FALSE)+L7*VLOOKUP($G7,'Claude Prices'!$A$5:$G$22,6,FALSE)+M7*VLOOKUP($G7,'Claude Prices'!$A$5:$G$22,7,FALSE))/1000000,0) | O7: =N7*ClaudeFxRate
A8: 46030 | B8: planning | C8: spec | F8: claude-opus-5-5 | G8: claude-opus-5-5 | H8: 40 | I8: 7000 | J8: 100000 | K8: 416668 | L8: 7133334 | M8: 103334 | N8: =IFERROR((I8*VLOOKUP($G8,'Claude Prices'!$A$5:$G$22,3,FALSE)+J8*VLOOKUP($G8,'Claude Prices'!$A$5:$G$22,4,FALSE)+K8*VLOOKUP($G8,'Claude Prices'!$A$5:$G$22,5,FALSE)+L8*VLOOKUP($G8,'Claude Prices'!$A$5:$G$22,6,FALSE)+M8*VLOOKUP($G8,'Claude Prices'!$A$5:$G$22,7,FALSE))/1000000,0) | O8: =N8*ClaudeFxRate
A9: 46034 | B9: planning | C9: architecture | F9: claude-opus-5-5 | G9: claude-opus-5-5 | H9: 39 | I9: 7111 | J9: 91111 | K9: 433333 | L9: 7577777 | M9: 100555 | N9: =IFERROR((I9*VLOOKUP($G9,'Claude Prices'!$A$5:$G$22,3,FALSE)+J9*VLOOKUP($G9,'Claude Prices'!$A$5:$G$22,4,FALSE)+K9*VLOOKUP($G9,'Claude Prices'!$A$5:$G$22,5,FALSE)+L9*VLOOKUP($G9,'Claude Prices'!$A$5:$G$22,6,FALSE)+M9*VLOOKUP($G9,'Claude Prices'!$A$5:$G$22,7,FALSE))/1000000,0) | O9: =N9*ClaudeFxRate
A10: 46035 | B10: planning | C10: architecture | F10: claude-opus-5-5 | G10: claude-opus-5-5 | H10: 39 | I10: 7111 | J10: 91111 | K10: 433333 | L10: 7577777 | M10: 100555 | N10: =IFERROR((I10*VLOOKUP($G10,'Claude Prices'!$A$5:$G$22,3,FALSE)+J10*VLOOKUP($G10,'Claude Prices'!$A$5:$G$22,4,FALSE)+K10*VLOOKUP($G10,'Claude Prices'!$A$5:$G$22,5,FALSE)+L10*VLOOKUP($G10,'Claude Prices'!$A$5:$G$22,6,FALSE)+M10*VLOOKUP($G10,'Claude Prices'!$A$5:$G$22,7,FALSE))/1000000,0) | O10: =N10*ClaudeFxRate
A11: 46036 | B11: planning | C11: architecture | F11: claude-opus-5-5 | G11: claude-opus-5-5 | H11: 39 | I11: 7111 | J11: 91111 | K11: 433333 | L11: 7577777 | M11: 100555 | N11: =IFERROR((I11*VLOOKUP($G11,'Claude Prices'!$A$5:$G$22,3,FALSE)+J11*VLOOKUP($G11,'Claude Prices'!$A$5:$G$22,4,FALSE)+K11*VLOOKUP($G11,'Claude Prices'!$A$5:$G$22,5,FALSE)+L11*VLOOKUP($G11,'Claude Prices'!$A$5:$G$22,6,FALSE)+M11*VLOOKUP($G11,'Claude Prices'!$A$5:$G$22,7,FALSE))/1000000,0) | O11: =N11*ClaudeFxRate
